<?xml version="1.0" ?>
<!--
  Author: Adeeb Abbas
  Date: 2023-02-01
  Description: This file is the URDF file for the Ackermann model we're using for our planning algorithms. The original comes from AgileX robotics 
  but I have modified it to fit our needs. The original can be found here: https://github.com/agilexrobotics/limo_ros
  License: MIT
  -->

<!-- =================================================================================== -->
<!-- |    This document was autogenerated by xacro from limo_ackerman.xacro            | -->
<!-- |    EDITING THIS FILE BY HAND IS NOT RECOMMENDED                                 | -->
<!-- =================================================================================== -->
<robot name="ackermann">
  <transmission name="front_right_wheel_trans" type="SimpleTransmission">
    <type>transmission_interface/SimpleTransmission</type>
    <actuator name="front_right_wheel_motor">
      <hardwareInterface>hardware_interface/VelocityJointInterface</hardwareInterface>
      <mechanicalReduction>1</mechanicalReduction>
    </actuator>
    <joint name="front_right_wheel">
      <hardwareInterface>hardware_interface/VelocityJointInterface</hardwareInterface>
    </joint>
  </transmission>
  <transmission name="front_left_wheel_trans" type="SimpleTransmission">
    <type>transmission_interface/SimpleTransmission</type>
    <actuator name="front_left_wheel_motor">
      <hardwareInterface>hardware_interface/VelocityJointInterface</hardwareInterface>
      <mechanicalReduction>1</mechanicalReduction>
    </actuator>
    <joint name="front_left_wheel">
      <hardwareInterface>hardware_interface/VelocityJointInterface</hardwareInterface>
    </joint>
  </transmission>
  <transmission name="rear_left_wheel_trans" type="SimpleTransmission">
    <type>transmission_interface/SimpleTransmission</type>
    <actuator name="rear_left_wheel_motor">
      <hardwareInterface>hardware_interface/VelocityJointInterface</hardwareInterface>
      <mechanicalReduction>1</mechanicalReduction>
    </actuator>
    <joint name="rear_left_wheel">
      <hardwareInterface>hardware_interface/VelocityJointInterface</hardwareInterface>
    </joint>
  </transmission>
  <transmission name="rear_right_wheel_trans" type="SimpleTransmission">
    <type>transmission_interface/SimpleTransmission</type>
    <actuator name="rear_right_wheel_motor">
      <hardwareInterface>hardware_interface/VelocityJointInterface</hardwareInterface>
      <mechanicalReduction>1</mechanicalReduction>
    </actuator>
    <joint name="rear_right_wheel">
      <hardwareInterface>hardware_interface/VelocityJointInterface</hardwareInterface>
    </joint>
  </transmission>
  <transmission name="left_steering_hinge_wheel_trans" type="SimpleTransmission">
    <type>transmission_interface/SimpleTransmission</type>
    <actuator name="left_steering_hinge_wheel_motor">
      <hardwareInterface>hardware_interface/EffortJointInterface</hardwareInterface>
      <mechanicalReduction>1</mechanicalReduction>
    </actuator>
    <joint name="left_steering_hinge_wheel">
      <hardwareInterface>hardware_interface/EffortJointInterface</hardwareInterface>
    </joint>
  </transmission>
  <transmission name="right_steering_hinge_wheel_trans" type="SimpleTransmission">
    <type>transmission_interface/SimpleTransmission</type>
    <actuator name="right_steering_hinge_wheel_motor">
      <hardwareInterface>hardware_interface/EffortJointInterface</hardwareInterface>
      <mechanicalReduction>1</mechanicalReduction>
    </actuator>
    <joint name="right_steering_hinge_wheel">
      <hardwareInterface>hardware_interface/EffortJointInterface</hardwareInterface>
    </joint>
  </transmission>
  <gazebo reference="laser_link">
    <sensor name="laser_sensor" type="ray">
      <pose>0 0 0 0 0 0</pose>
      <visualize>false</visualize>
      <update_rate>8</update_rate>
      <ray>
        <scan>
          <horizontal>
            <samples>720</samples>
            <resolution>1</resolution>
            <min_angle>-2.09439504</min_angle>
            <max_angle>2.09439504</max_angle>
          </horizontal>
        </scan>
        <range>
          <min>0.05</min>
          <max>8.0</max>
          <resolution>0.01</resolution>
        </range>
        <noise>
          <type>gaussian</type>
          <mean>0.0</mean>
          <stddev>0.01</stddev>
        </noise>
      </ray>
      <plugin filename="libgazebo_ros_laser.so" name="gazebo_ros_laser_sensor">
        <topicName>/limo/scan</topicName>
        <frameName>laser_link</frameName>
      </plugin>
    </sensor>
  </gazebo>
  <gazebo reference="depth_camera_link">
    <sensor name="sensor_camera" type="depth">
      <pose>0.0 0.0 0.0 0.0 0.0 0.0</pose>
      <always_on>true</always_on>
      <visualize>true</visualize>
      <update_rate>10.0</update_rate>
      <camera name="head">
        <horizontal_fov>1.3962634</horizontal_fov>
        <image>
          <width>640</width>
          <height>480</height>
          <format>R8G8B8</format>
        </image>
        <clip>
          <near>0.02</near>
          <far>300</far>
        </clip>
      </camera>
      <plugin filename="libgazebo_ros_openni_kinect.so" name="gazebo_ros_depth_camera_sensor">
        <baseline>0.2</baseline>
        <alwaysOn>true</alwaysOn>
        <!-- Keep this zero, update_rate in the parent <sensor> tag
                will control the frame rate. -->
        <updateRate>0.0</updateRate>
        <cameraName>camera_ir</cameraName>
        <imageTopicName>/limo/color/image_raw</imageTopicName>
        <cameraInfoTopicName>/limo/color/camera_info</cameraInfoTopicName>
        <depthImageTopicName>/limo/depth/image_raw</depthImageTopicName>
        <depthImageCameraInfoTopicName>/limo/depth/camera_info</depthImageCameraInfoTopicName>
        <pointCloudTopicName>/limo/depth/points</pointCloudTopicName>
        <frameName>depth_link</frameName>
        <cameraname>depth_camera_link</cameraname>
        <pointCloudCutoff>0.5</pointCloudCutoff>
        <pointCloudCutoffMax>3.0</pointCloudCutoffMax>
        <distortionK1>0</distortionK1>
        <distortionK2>0</distortionK2>
        <distortionK3>0</distortionK3>
        <distortionT1>0</distortionT1>
        <distortionT2>0</distortionT2>
        <CxPrime>0</CxPrime>
        <Cx>0</Cx>
        <Cy>0</Cy>
        <focalLength>0</focalLength>
        <hackBaseline>0</hackBaseline>
      </plugin>
    </sensor>
  </gazebo>
  <gazebo reference="imu_link">
    <gravity>true</gravity>
    <sensor name="imu_sensor" type="imu">
      <always_on>true</always_on>
      <update_rate>100</update_rate>
      <visualize>true</visualize>
      <topic>__default_topic__</topic>
      <plugin filename="libgazebo_ros_imu_sensor.so" name="imu_plugin">
        <topicName>/limo/imu</topicName>
        <bodyName>imu_link</bodyName>
        <updateRateHZ>100.0</updateRateHZ>
        <gaussianNoise>0.001</gaussianNoise>
        <xyzOffset>0 0 0</xyzOffset>
        <rpyOffset>0 0 0</rpyOffset>
        <frameName>imu_link</frameName>
      </plugin>
      <pose>0 0 0 0 0 0</pose>
    </sensor>
  </gazebo>
  <gazebo>
    <mu1 value="10"/>
    <mu2 value="10"/>
    <kp value="10000000.0"/>
    <kd value="1.0"/>
    <fdir1 value="1 0 0"/>
    <minDepth value="0.001"/>
    <maxContacts value="64"/>
  </gazebo>
  <gazebo>
    <plugin filename="libgazebo_ros_control.so" name="gazebo_ros_control">
      <robotNamespace>/</robotNamespace>
    </plugin>
    <plugin filename="libgazebo_ros_ackerman.so" name="four_diff_controller">
      <updateRate>100.0</updateRate>
      <robotNamespace>/</robotNamespace>
      <leftFrontJoint>front_left_wheel</leftFrontJoint>
      <rightFrontJoint>front_right_wheel</rightFrontJoint>
      <leftRearJoint>rear_left_wheel</leftRearJoint>
      <rightRearJoint>rear_right_wheel</rightRearJoint>
      <leftHingeJoint>left_steering_hinge_wheel</leftHingeJoint>
      <rightHingeJoint>right_steering_hinge_wheel</rightHingeJoint>
      <wheelSeparation>0.172</wheelSeparation>
      <wheelDiameter>0.09</wheelDiameter>
      <robotBaseFrame>base_footprint</robotBaseFrame>
      <commandTopic>cmd_vel</commandTopic>
      <torque>50</torque>
      <broadcastTF>true</broadcastTF>
      <odometryTopic>odom</odometryTopic>
      <odometryFrame>odom</odometryFrame>
      <covariance_x>0.000100</covariance_x>
      <covariance_y>0.000100</covariance_y>
      <covariance_yaw>0.010000</covariance_yaw>
    </plugin>
  </gazebo>
  <link name="base_footprint"/>
  <joint name="base_joint" type="fixed">
    <parent link="base_footprint"/>
    <child link="base_link"/>
    <origin rpy="0 0 0" xyz="0.0 0.0 0.15"/>
  </joint>
  <!-- Base link -->
  <link name="base_link">
    <visual>
      <origin rpy="0 0 1.57" xyz="0 0 -0.15"/>
      <geometry>
        <mesh filename="package://ackermann/meshes/limo_base.dae" scale="1 1 1"/>
      </geometry>
    </visual>
    <collision>
      <origin rpy="0 0 0" xyz="0 0 0"/>
      <geometry>
        <box size="0.13 0.12 0.1"/>
      </geometry>
    </collision>
  </link>
  <link name="inertial_link">
    <inertial>
      <origin xyz="0.0 0.0 0.0"/>
      <mass value="2.1557"/>
      <inertia ixx="0.24" ixy="0" ixz="0" iyy="0.96" iyz="0" izz="0.96"/>
    </inertial>
  </link>
  <joint name="inertial_joint" type="fixed">
    <origin rpy="0 0 0" xyz="0 0 0"/>
    <parent link="base_link"/>
    <child link="inertial_link"/>
  </joint>
  <link name="laser_link">
    <pose>0 0 0 0 0 0</pose>
    <inertial>
      <mass value="0.1"/>
      <origin rpy="0 0 0" xyz="0.0 0 0"/>
      <inertia ixx="1e-6" ixy="0" ixz="0" iyy="1e-6" iyz="0" izz="1e-6"/>
    </inertial>
    <visual name="laser_visual">
      <origin rpy="0 0 0" xyz="0 0 0"/>
      <geometry>
        <cylinder length="0.01" radius="0.02"/>
      </geometry>
      <!-- <material name="laser_material">
        <ambient>0.1 0.1 0.1 1</ambient>
        <diffuse>0.1 0.1 0.2 1</diffuse>
        <specular>0 0 0 0</specular>
        <emissive>0 0 0 1</emissive>
      </material> -->
    </visual>
    <collision name="laser_collision">
      <origin rpy="0 0 0" xyz="0 0 0"/>
      <geometry>
        <cylinder length="0.016" radius="0.032"/>
      </geometry>
    </collision>
  </link>
  <joint name="laser_joint" type="fixed">
    <origin rpy="0 0 0" xyz="0.103 0 -0.034"/>
    <child link="laser_link"/>
    <parent link="base_link"/>
  </joint>
  <gazebo reference="laser_link">
    <material>Gazebo/Yellow</material>
  </gazebo>
  <link name="depth_camera_link">
    <pose>0 0 0 0 0 0</pose>
    <inertial>
      <mass value="0.1"/>
      <origin rpy="0 0 0" xyz="0.0 0 0"/>
      <inertia ixx="1e-6" ixy="0" ixz="0" iyy="1e-6" iyz="0" izz="1e-6"/>
    </inertial>
    <visual name="depth_camera_visual">
      <origin rpy="0 0 0" xyz="0 0 0"/>
      <geometry>
        <box size="0.02 0.06 0.015"/>
      </geometry>
      <!-- <material name="depth_camera_material"> -->
        <!-- <ambient>0.1 0.1 0.1 1</ambient>
        <diffuse>0.1 0.1 0.2 1</diffuse>
        <specular>0 0 0 0</specular>
        <emissive>0 0 0 1</emissive> -->
      <!-- </material> -->
    </visual>
    <collision name="depth_camera_collision">
      <origin rpy="0 0 0" xyz="0 0 0"/>
      <geometry>
        <box size="0.02 0.06 0.015"/>
      </geometry>
    </collision>
  </link>
  <joint name="depth_camera_joint" type="fixed">
    <origin rpy="0 0 0" xyz="0.084 0 0.03"/>
    <child link="depth_camera_link"/>
    <parent link="base_link"/>
  </joint>
  <link name="depth_link"/>
  <joint name="depth_camera_to_camera_joint" type="fixed">
    <origin rpy="-1.570795 0 -1.570795 " xyz="0 0 0"/>
    <parent link="depth_camera_link"/>
    <child link="depth_link"/>
  </joint>
  <gazebo reference="depth_camera_link">
    <material>Gazebo/Yellow</material>
  </gazebo>
  <link name="imu_link">
    <pose>0 0 0 0 0 0</pose>
    <inertial>
      <mass value="0.01"/>
      <origin rpy="0 0 0" xyz="0.0 0 0"/>
      <inertia ixx="1e-7" ixy="0" ixz="0" iyy="1e-7" iyz="0" izz="1e-7"/>
    </inertial>
    <visual name="imu_visual">
      <origin rpy="0 0 0" xyz="0 0 0"/>
      <geometry>
        <box size="0.001 0.001 0.001"/>
      </geometry>
      <!-- <material name="imu_material"> -->
        <!-- <ambient>0.1 0.1 0.1 1</ambient>
        <diffuse>0.1 0.1 0.2 1</diffuse>
        <specular>0 0 0 0</specular>
        <emissive>0 0 0 1</emissive> -->
      <!-- </material> -->
    </visual>
    <collision name="imu_collision">
      <origin rpy="0 0 0" xyz="0 0 0"/>
      <geometry>
        <box size="0.001 0.001 0.001"/>
      </geometry>
    </collision>
  </link>
  <joint name="imu_joint" type="fixed">
    <origin rpy="0 0 0" xyz="0.0 0 -0.1"/>
    <child link="imu_link"/>
    <parent link="base_link"/>
  </joint>
  <gazebo reference="imu_link">
    <material>Gazebo/Yellow</material>
  </gazebo>
  <link name="left_steering_hinge">
    <inertial>
      <mass value="0.25"/>
      <inertia ixx="0.00525" ixy="0" ixz="0" iyy="0.00035" iyz="0" izz="0.00525"/>
      <origin xyz="0 0 0"/>
    </inertial>
    <visual>
      <origin rpy="0 0 0" xyz="0 0 0"/>
      <geometry>
        <cylinder length="0.0001" radius="0.0001"/>
      </geometry>
    </visual>
    <collision>
      <origin rpy="1.57 0 0" xyz="0 0.0225 0"/>
      <geometry>
        <cylinder length="0.045" radius="0.034999999999999996"/>
      </geometry>
    </collision>
  </link>
  <joint name="left_steering_hinge_wheel" type="revolute">
    <parent link="base_link"/>
    <child link="left_steering_hinge"/>
    <origin rpy="0 0  0" xyz="0.1 0.07 -0.100998"/>
    <axis xyz="0 0 1"/>
    <limit effort="5" lower="-0.523598767" upper="0.523598767" velocity="0.5"/>
    <dynamics damping="1.0" friction="2.0"/>
  </joint>
  <link name="front_left_wheel_link">
    <inertial>
      <mass value="0.25"/>
      <inertia ixx="0.00525" ixy="0" ixz="0" iyy="0.00035" iyz="0" izz="0.00525"/>
      <origin xyz="0 0 0"/>
    </inertial>
    <visual>
      <origin rpy="0 0 0" xyz="0 0 0"/>
      <geometry>
        <mesh filename="package://ackermann/meshes/limo_wheel.dae"/>
      </geometry>
    </visual>
    <collision>
      <origin rpy="1.57 0 0" xyz="0 0.0225 0"/>
      <geometry>
        <cylinder length="0.045" radius="0.045"/>
      </geometry>
    </collision>
  </link>
  <joint name="front_left_wheel" type="continuous">
    <parent link="left_steering_hinge"/>
    <child link="front_left_wheel_link"/>
    <origin rpy="0 0  0" xyz="0 0 0"/>
    <axis xyz="0 1 0"/>
  </joint>
  <link name="right_steering_hinge">
    <inertial>
      <mass value="0.25"/>
      <inertia ixx="0.00525" ixy="0" ixz="0" iyy="0.00035" iyz="0" izz="0.00525"/>
      <origin xyz="0 0 0"/>
    </inertial>
    <visual>
      <origin rpy="0 0 0" xyz="0 0 0"/>
      <geometry>
        <cylinder length="0.0001" radius="0.0001"/>
      </geometry>
    </visual>
    <collision>
      <origin rpy="1.57 0 0" xyz="0 0.0225 0"/>
      <geometry>
        <cylinder length="0.045" radius="0.034999999999999996"/>
      </geometry>
    </collision>
  </link>
  <joint name="right_steering_hinge_wheel" type="revolute">
    <parent link="base_link"/>
    <child link="right_steering_hinge"/>
    <origin rpy="3.14159 0 0" xyz="0.1 -0.07 -0.100998"/>
    <axis xyz="0 0 -1"/>
    <limit effort="5" lower="-0.523598767" upper="0.523598767" velocity="0.5"/>
    <dynamics damping="1.0" friction="2.0"/>
  </joint>
  <link name="front_right_wheel_link">
    <inertial>
      <mass value="0.25"/>
      <inertia ixx="0.00525" ixy="0" ixz="0" iyy="0.00035" iyz="0" izz="0.00525"/>
      <origin xyz="0 0 0"/>
    </inertial>
    <visual>
      <origin rpy="0 0 0" xyz="0 0 0"/>
      <geometry>
        <mesh filename="package://ackermann/meshes/limo_wheel.dae"/>
      </geometry>
    </visual>
    <collision>
      <origin rpy="1.57 0 0" xyz="0 0.0225 0"/>
      <geometry>
        <cylinder length="0.045" radius="0.045"/>
      </geometry>
    </collision>
  </link>
  <joint name="front_right_wheel" type="continuous">
    <parent link="right_steering_hinge"/>
    <child link="front_right_wheel_link"/>
    <origin rpy="0 0  0" xyz="0 0 0"/>
    <axis xyz="0 -1 0"/>
  </joint>
  <link name="rear_left_wheel_link">
    <inertial>
      <origin xyz="0 0 0"/>
      <mass value="0.5"/>
      <inertia ixx="0.01055" ixy="0" ixz="0" iyy="0.00075" iyz="0" izz="0.01055"/>
    </inertial>
    <visual>
      <origin rpy="0 0 0" xyz="0 0 0"/>
      <geometry>
        <mesh filename="package://ackermann/meshes/limo_wheel.dae"/>
      </geometry>
    </visual>
    <collision>
      <origin rpy="1.57 0 0" xyz="0 0.0225 0"/>
      <geometry>
        <cylinder length="0.045" radius="0.045"/>
      </geometry>
    </collision>
  </link>
  <joint name="rear_left_wheel" type="continuous">
    <parent link="base_link"/>
    <child link="rear_left_wheel_link"/>
    <origin rpy="0 0 0" xyz="-0.1 0.07 -0.100998"/>
    <axis xyz="0 1 0"/>
  </joint>
  <link name="rear_right_wheel_link">
    <inertial>
      <origin xyz="0 0 0"/>
      <mass value="0.5"/>
      <inertia ixx="0.01055" ixy="0" ixz="0" iyy="0.00075" iyz="0" izz="0.01055"/>
    </inertial>
    <visual>
      <origin rpy="0 0 0" xyz="0 0 0"/>
      <geometry>
        <mesh filename="package://ackermann/meshes/limo_wheel.dae"/>
      </geometry>
    </visual>
    <collision>
      <origin rpy="1.57 0 0" xyz="0 0.0225 0"/>
      <geometry>
        <cylinder length="0.045" radius="0.045"/>
      </geometry>
    </collision>
  </link>
  <joint name="rear_right_wheel" type="continuous">
    <parent link="base_link"/>
    <child link="rear_right_wheel_link"/>
    <origin rpy="3.14159 0 0" xyz="-0.1 -0.07 -0.100998"/>
    <axis xyz="0 -1 0"/>
  </joint>
</robot>