<?xml version="1.0"?>

<robot name="limo_ackerman">

    <!-- Variables -->
    <!-- <xacro:property name="M_PI" value="3.14159"/> -->

    <!-- 
    <xacro:property name="base_x_size" value="0.13" />
    <xacro:property name="base_y_size" value="0.12" />
    <xacro:property name="base_z_size" value="0.10" />

    <xacro:property name="wheelbase" value="0.2"/>
    <xacro:property name="track" value="0.14"/>
    <xacro:property name="wheel_vertical_offset" value="-0.100998" />
    <xacro:property name="base_mass" value="2.1557"/>

    <xacro:property name="wheel_length" value="0.045" />
    <xacro:property name="wheel_radius" value="0.045" />
    -->

    <link name="base_footprint"/>

    <joint name="base_joint" type="fixed">
    <parent link="base_footprint"/>
    <child link="base_link"/>
    <origin xyz="0.0 0.0 0.15" rpy="0 0 0"/>
    </joint>
    <!-- Base link -->
    <link name="base_link">
        <visual>
            <origin xyz="0 0 -0.15" rpy="0 0 1.57" />
            <geometry>
                <mesh filename="package://ackermann/meshes/limo_base.dae" scale="1 1 1"/>
            </geometry>
        </visual>
        <collision>
            <origin xyz="0 0 0" rpy="0 0 0" />
          <geometry>
              <box size="0.13 0.12 0.10"/>
          </geometry>
        </collision>
    </link>

    <link name="inertial_link">
        <inertial>
            <origin xyz="0.0 0.0 0.0" />
            <mass value="2.1557" />
            <inertia ixx="0.24" ixy="0" ixz="0" 
                     iyy="0.96" iyz="0" 
                     izz="0.96" />
        </inertial>
    </link>

    <joint name="inertial_joint" type="fixed">
        <origin xyz="0 0 0" rpy="0 0 0" />
        <parent link="base_link" />
        <child link="inertial_link" />
    </joint>

    <xacro:limo_laser parent_prefix="base_link" frame_prefix="laser">
        <origin xyz="0.103 0 -0.034" rpy="0 0 0"/>
    </xacro:limo_laser>

    <xacro:limo_depth_camera parent_prefix="base_link" frame_prefix="depth_camera">
        <origin xyz="0.084 0 0.03" rpy="0 0 0"/>
    </xacro:limo_depth_camera>

    <xacro:limo_imu parent_prefix="base_link" frame_prefix="imu">
        <origin xyz="0.0 0 -0.1" rpy="0 0 0"/>
    </xacro:limo_imu>
    
    <xacro:limo_left_steering_hinge parent_prefix="base_link" wheel_prefix="left_steering_hinge">
        <origin xyz="0.1 0.14/2 -0.100998" rpy="0 0  0" />
    </xacro:limo_left_steering_hinge>

    <xacro:limo_right_steering_hinge parent_prefix="base_link" wheel_prefix="right_steering_hinge">
        <origin xyz="0.1 -0.07 -0.100998" rpy="3.14 0 0" />
    </xacro:limo_right_steering_hinge>


    <link name="rear_left_wheel_link">
        <inertial>
            <origin xyz="0 0 0" />
            <mass value="0.5" />
            <inertia ixx="0.01055" ixy="0" ixz="0" iyy="0.00075" iyz="0" izz="0.01055" /> 
        </inertial>
        <visual>
            <origin xyz="0 0 0" rpy="0 0 0" />
            <geometry>
                <mesh filename="package://ackermann/meshes/limo_wheel.dae" />
            </geometry>
        </visual>
        <collision>
            <origin xyz="0 0.0225 0" rpy="1.57 0 0" />
          <geometry>
              <cylinder length="0.045" radius="0.045" />
          </geometry>
        </collision>
    </link>
    <joint name="rear_left_wheel_joint" type="continuous">
        <parent link="base_link"/>
        <child link="rear_left_wheel_link"/>
        <origin xyz="-0.1 0.07 -0.100998" rpy="0 0 0" />
        <axis xyz="0 1 0"/>
    </joint>

    <transmission name="rear_left_wheel_transmission">
      <type>transmission_interface/SimpleTransmission</type>
      <joint name="rear_left_wheel_joint">
        <hardwareInterface>VelocityJointInterface</hardwareInterface>
      </joint>
      <actuator name="rear_left_wheel_motor">
        <hardwareInterface>VelocityJointInterface</hardwareInterface>
        <mechanicalReduction>1</mechanicalReduction>
      </actuator>
    </transmission>

    <link name="rear_right_wheel_link">
        <inertial>
            <origin xyz="0 0 0" />
            <mass value="0.5" />
            <inertia ixx="0.01055" ixy="0" ixz="0" iyy="0.00075" iyz="0" izz="0.01055" /> 
        </inertial>
        <visual>
            <origin xyz="0 0 0" rpy="0 0 0" />
            <geometry>
                <mesh filename="package://ackermann/meshes/limo_wheel.dae" />
            </geometry>
        </visual>
            <collision>
                <origin xyz="0 0.0025 0" rpy="1.57 0 0" />
              <geometry>
                  <cylinder length="0.045" radius="0.045" />
              </geometry>
            </collision>
        </link>

        <joint name="rear_right_wheel_joint" type="continuous">
            <parent link="base_link"/>
            <child link="rear_right_wheel_link"/>
            <origin xyz="-0.1 -0.07 -0.100998" rpy="3.14 0 0" />
            <axis xyz="0 -1 0"/>
        </joint>

    <transmission name="rear_right_wheel_transmission">
      <type>transmission_interface/SimpleTransmission</type>
      <joint name="rear_right_wheel_joint">
        <hardwareInterface>VelocityJointInterface</hardwareInterface>
      </joint>
      <actuator name="rear_right_wheel_motor">
        <hardwareInterface>VelocityJointInterface</hardwareInterface>
        <mechanicalReduction>1</mechanicalReduction>
      </actuator>
    </transmission>
</robot>
